2022-06-26 19:45:04,494:WARNING:discord.client: PyNaCl is not installed, voice will NOT be supported
2022-06-30 03:22:14,157:ERROR:discord.client: Attempting a reconnect in 1.76s
Traceback (most recent call last):
  File "/home/pi/.local/lib/python3.9/site-packages/discord/client.py", line 566, in connect
    await self.ws.poll_event()
  File "/home/pi/.local/lib/python3.9/site-packages/discord/gateway.py", line 582, in poll_event
    raise ConnectionClosed(self.socket, shard_id=self.shard_id, code=code) from None
discord.errors.ConnectionClosed: Shard ID None WebSocket closed with 1000
2022-06-30 03:22:35,948:ERROR:discord.client: Attempting a reconnect in 0.42s
Traceback (most recent call last):
  File "/home/pi/.local/lib/python3.9/site-packages/aiohttp/connector.py", line 999, in _create_direct_connection
    hosts = await asyncio.shield(host_resolved)
  File "/home/pi/.local/lib/python3.9/site-packages/aiohttp/connector.py", line 865, in _resolve_host
    addrs = await self._resolver.resolve(host, port, family=self._family)
  File "/home/pi/.local/lib/python3.9/site-packages/aiohttp/resolver.py", line 31, in resolve
    infos = await self._loop.getaddrinfo(
  File "/usr/lib/python3.9/asyncio/base_events.py", line 856, in getaddrinfo
    return await self.run_in_executor(
  File "/usr/lib/python3.9/concurrent/futures/thread.py", line 52, in run
    result = self.fn(*self.args, **self.kwargs)
  File "/usr/lib/python3.9/socket.py", line 953, in getaddrinfo
    for res in _socket.getaddrinfo(host, port, family, type, proto, flags):
socket.gaierror: [Errno -3] Temporary failure in name resolution

The above exception was the direct cause of the following exception:

Traceback (most recent call last):
  File "/home/pi/.local/lib/python3.9/site-packages/discord/client.py", line 563, in connect
    self.ws = await asyncio.wait_for(coro, timeout=60.0)
  File "/usr/lib/python3.9/asyncio/tasks.py", line 481, in wait_for
    return fut.result()
  File "/home/pi/.local/lib/python3.9/site-packages/discord/gateway.py", line 305, in from_client
    gateway = gateway or await client.http.get_gateway()
  File "/home/pi/.local/lib/python3.9/site-packages/discord/http.py", line 967, in get_gateway
    data = await self.request(Route('GET', '/gateway'))
  File "/home/pi/.local/lib/python3.9/site-packages/discord/http.py", line 192, in request
    async with self.__session.request(method, url, **kwargs) as r:
  File "/home/pi/.local/lib/python3.9/site-packages/aiohttp/client.py", line 1117, in __aenter__
    self._resp = await self._coro
  File "/home/pi/.local/lib/python3.9/site-packages/aiohttp/client.py", line 520, in _request
    conn = await self._connector.connect(
  File "/home/pi/.local/lib/python3.9/site-packages/aiohttp/connector.py", line 535, in connect
    proto = await self._create_connection(req, traces, timeout)
  File "/home/pi/.local/lib/python3.9/site-packages/aiohttp/connector.py", line 892, in _create_connection
    _, proto = await self._create_direct_connection(req, traces, timeout)
  File "/home/pi/.local/lib/python3.9/site-packages/aiohttp/connector.py", line 1011, in _create_direct_connection
    raise ClientConnectorError(req.connection_key, exc) from exc
aiohttp.client_exceptions.ClientConnectorError: Cannot connect to host discord.com:443 ssl:default [Temporary failure in name resolution]
2022-06-30 03:22:56,419:ERROR:discord.client: Attempting a reconnect in 2.58s
Traceback (most recent call last):
  File "/home/pi/.local/lib/python3.9/site-packages/aiohttp/connector.py", line 999, in _create_direct_connection
    hosts = await asyncio.shield(host_resolved)
  File "/home/pi/.local/lib/python3.9/site-packages/aiohttp/connector.py", line 865, in _resolve_host
    addrs = await self._resolver.resolve(host, port, family=self._family)
  File "/home/pi/.local/lib/python3.9/site-packages/aiohttp/resolver.py", line 31, in resolve
    infos = await self._loop.getaddrinfo(
  File "/usr/lib/python3.9/asyncio/base_events.py", line 856, in getaddrinfo
    return await self.run_in_executor(
  File "/usr/lib/python3.9/concurrent/futures/thread.py", line 52, in run
    result = self.fn(*self.args, **self.kwargs)
  File "/usr/lib/python3.9/socket.py", line 953, in getaddrinfo
    for res in _socket.getaddrinfo(host, port, family, type, proto, flags):
socket.gaierror: [Errno -3] Temporary failure in name resolution

The above exception was the direct cause of the following exception:

Traceback (most recent call last):
  File "/home/pi/.local/lib/python3.9/site-packages/discord/client.py", line 563, in connect
    self.ws = await asyncio.wait_for(coro, timeout=60.0)
  File "/usr/lib/python3.9/asyncio/tasks.py", line 481, in wait_for
    return fut.result()
  File "/home/pi/.local/lib/python3.9/site-packages/discord/gateway.py", line 305, in from_client
    gateway = gateway or await client.http.get_gateway()
  File "/home/pi/.local/lib/python3.9/site-packages/discord/http.py", line 967, in get_gateway
    data = await self.request(Route('GET', '/gateway'))
  File "/home/pi/.local/lib/python3.9/site-packages/discord/http.py", line 192, in request
    async with self.__session.request(method, url, **kwargs) as r:
  File "/home/pi/.local/lib/python3.9/site-packages/aiohttp/client.py", line 1117, in __aenter__
    self._resp = await self._coro
  File "/home/pi/.local/lib/python3.9/site-packages/aiohttp/client.py", line 520, in _request
    conn = await self._connector.connect(
  File "/home/pi/.local/lib/python3.9/site-packages/aiohttp/connector.py", line 535, in connect
    proto = await self._create_connection(req, traces, timeout)
  File "/home/pi/.local/lib/python3.9/site-packages/aiohttp/connector.py", line 892, in _create_connection
    _, proto = await self._create_direct_connection(req, traces, timeout)
  File "/home/pi/.local/lib/python3.9/site-packages/aiohttp/connector.py", line 1011, in _create_direct_connection
    raise ClientConnectorError(req.connection_key, exc) from exc
aiohttp.client_exceptions.ClientConnectorError: Cannot connect to host discord.com:443 ssl:default [Temporary failure in name resolution]
2022-06-30 03:23:19,028:ERROR:discord.client: Attempting a reconnect in 14.71s
Traceback (most recent call last):
  File "/home/pi/.local/lib/python3.9/site-packages/aiohttp/connector.py", line 999, in _create_direct_connection
    hosts = await asyncio.shield(host_resolved)
  File "/home/pi/.local/lib/python3.9/site-packages/aiohttp/connector.py", line 865, in _resolve_host
    addrs = await self._resolver.resolve(host, port, family=self._family)
  File "/home/pi/.local/lib/python3.9/site-packages/aiohttp/resolver.py", line 31, in resolve
    infos = await self._loop.getaddrinfo(
  File "/usr/lib/python3.9/asyncio/base_events.py", line 856, in getaddrinfo
    return await self.run_in_executor(
  File "/usr/lib/python3.9/concurrent/futures/thread.py", line 52, in run
    result = self.fn(*self.args, **self.kwargs)
  File "/usr/lib/python3.9/socket.py", line 953, in getaddrinfo
    for res in _socket.getaddrinfo(host, port, family, type, proto, flags):
socket.gaierror: [Errno -3] Temporary failure in name resolution

The above exception was the direct cause of the following exception:

Traceback (most recent call last):
  File "/home/pi/.local/lib/python3.9/site-packages/discord/client.py", line 563, in connect
    self.ws = await asyncio.wait_for(coro, timeout=60.0)
  File "/usr/lib/python3.9/asyncio/tasks.py", line 481, in wait_for
    return fut.result()
  File "/home/pi/.local/lib/python3.9/site-packages/discord/gateway.py", line 305, in from_client
    gateway = gateway or await client.http.get_gateway()
  File "/home/pi/.local/lib/python3.9/site-packages/discord/http.py", line 967, in get_gateway
    data = await self.request(Route('GET', '/gateway'))
  File "/home/pi/.local/lib/python3.9/site-packages/discord/http.py", line 192, in request
    async with self.__session.request(method, url, **kwargs) as r:
  File "/home/pi/.local/lib/python3.9/site-packages/aiohttp/client.py", line 1117, in __aenter__
    self._resp = await self._coro
  File "/home/pi/.local/lib/python3.9/site-packages/aiohttp/client.py", line 520, in _request
    conn = await self._connector.connect(
  File "/home/pi/.local/lib/python3.9/site-packages/aiohttp/connector.py", line 535, in connect
    proto = await self._create_connection(req, traces, timeout)
  File "/home/pi/.local/lib/python3.9/site-packages/aiohttp/connector.py", line 892, in _create_connection
    _, proto = await self._create_direct_connection(req, traces, timeout)
  File "/home/pi/.local/lib/python3.9/site-packages/aiohttp/connector.py", line 1011, in _create_direct_connection
    raise ClientConnectorError(req.connection_key, exc) from exc
aiohttp.client_exceptions.ClientConnectorError: Cannot connect to host discord.com:443 ssl:default [Temporary failure in name resolution]
2022-06-30 03:23:53,787:ERROR:discord.client: Attempting a reconnect in 16.25s
Traceback (most recent call last):
  File "/home/pi/.local/lib/python3.9/site-packages/aiohttp/connector.py", line 999, in _create_direct_connection
    hosts = await asyncio.shield(host_resolved)
  File "/home/pi/.local/lib/python3.9/site-packages/aiohttp/connector.py", line 865, in _resolve_host
    addrs = await self._resolver.resolve(host, port, family=self._family)
  File "/home/pi/.local/lib/python3.9/site-packages/aiohttp/resolver.py", line 31, in resolve
    infos = await self._loop.getaddrinfo(
  File "/usr/lib/python3.9/asyncio/base_events.py", line 856, in getaddrinfo
    return await self.run_in_executor(
  File "/usr/lib/python3.9/concurrent/futures/thread.py", line 52, in run
    result = self.fn(*self.args, **self.kwargs)
  File "/usr/lib/python3.9/socket.py", line 953, in getaddrinfo
    for res in _socket.getaddrinfo(host, port, family, type, proto, flags):
socket.gaierror: [Errno -3] Temporary failure in name resolution

The above exception was the direct cause of the following exception:

Traceback (most recent call last):
  File "/home/pi/.local/lib/python3.9/site-packages/discord/client.py", line 563, in connect
    self.ws = await asyncio.wait_for(coro, timeout=60.0)
  File "/usr/lib/python3.9/asyncio/tasks.py", line 481, in wait_for
    return fut.result()
  File "/home/pi/.local/lib/python3.9/site-packages/discord/gateway.py", line 305, in from_client
    gateway = gateway or await client.http.get_gateway()
  File "/home/pi/.local/lib/python3.9/site-packages/discord/http.py", line 967, in get_gateway
    data = await self.request(Route('GET', '/gateway'))
  File "/home/pi/.local/lib/python3.9/site-packages/discord/http.py", line 192, in request
    async with self.__session.request(method, url, **kwargs) as r:
  File "/home/pi/.local/lib/python3.9/site-packages/aiohttp/client.py", line 1117, in __aenter__
    self._resp = await self._coro
  File "/home/pi/.local/lib/python3.9/site-packages/aiohttp/client.py", line 520, in _request
    conn = await self._connector.connect(
  File "/home/pi/.local/lib/python3.9/site-packages/aiohttp/connector.py", line 535, in connect
    proto = await self._create_connection(req, traces, timeout)
  File "/home/pi/.local/lib/python3.9/site-packages/aiohttp/connector.py", line 892, in _create_connection
    _, proto = await self._create_direct_connection(req, traces, timeout)
  File "/home/pi/.local/lib/python3.9/site-packages/aiohttp/connector.py", line 1011, in _create_direct_connection
    raise ClientConnectorError(req.connection_key, exc) from exc
aiohttp.client_exceptions.ClientConnectorError: Cannot connect to host discord.com:443 ssl:default [Temporary failure in name resolution]
2022-06-30 03:24:30,087:ERROR:discord.client: Attempting a reconnect in 8.98s
Traceback (most recent call last):
  File "/home/pi/.local/lib/python3.9/site-packages/aiohttp/connector.py", line 999, in _create_direct_connection
    hosts = await asyncio.shield(host_resolved)
  File "/home/pi/.local/lib/python3.9/site-packages/aiohttp/connector.py", line 865, in _resolve_host
    addrs = await self._resolver.resolve(host, port, family=self._family)
  File "/home/pi/.local/lib/python3.9/site-packages/aiohttp/resolver.py", line 31, in resolve
    infos = await self._loop.getaddrinfo(
  File "/usr/lib/python3.9/asyncio/base_events.py", line 856, in getaddrinfo
    return await self.run_in_executor(
  File "/usr/lib/python3.9/concurrent/futures/thread.py", line 52, in run
    result = self.fn(*self.args, **self.kwargs)
  File "/usr/lib/python3.9/socket.py", line 953, in getaddrinfo
    for res in _socket.getaddrinfo(host, port, family, type, proto, flags):
socket.gaierror: [Errno -3] Temporary failure in name resolution

The above exception was the direct cause of the following exception:

Traceback (most recent call last):
  File "/home/pi/.local/lib/python3.9/site-packages/discord/client.py", line 563, in connect
    self.ws = await asyncio.wait_for(coro, timeout=60.0)
  File "/usr/lib/python3.9/asyncio/tasks.py", line 481, in wait_for
    return fut.result()
  File "/home/pi/.local/lib/python3.9/site-packages/discord/gateway.py", line 305, in from_client
    gateway = gateway or await client.http.get_gateway()
  File "/home/pi/.local/lib/python3.9/site-packages/discord/http.py", line 967, in get_gateway
    data = await self.request(Route('GET', '/gateway'))
  File "/home/pi/.local/lib/python3.9/site-packages/discord/http.py", line 192, in request
    async with self.__session.request(method, url, **kwargs) as r:
  File "/home/pi/.local/lib/python3.9/site-packages/aiohttp/client.py", line 1117, in __aenter__
    self._resp = await self._coro
  File "/home/pi/.local/lib/python3.9/site-packages/aiohttp/client.py", line 520, in _request
    conn = await self._connector.connect(
  File "/home/pi/.local/lib/python3.9/site-packages/aiohttp/connector.py", line 535, in connect
    proto = await self._create_connection(req, traces, timeout)
  File "/home/pi/.local/lib/python3.9/site-packages/aiohttp/connector.py", line 892, in _create_connection
    _, proto = await self._create_direct_connection(req, traces, timeout)
  File "/home/pi/.local/lib/python3.9/site-packages/aiohttp/connector.py", line 1011, in _create_direct_connection
    raise ClientConnectorError(req.connection_key, exc) from exc
aiohttp.client_exceptions.ClientConnectorError: Cannot connect to host discord.com:443 ssl:default [Temporary failure in name resolution]
2022-06-30 03:24:59,105:ERROR:discord.client: Attempting a reconnect in 114.92s
Traceback (most recent call last):
  File "/home/pi/.local/lib/python3.9/site-packages/aiohttp/connector.py", line 999, in _create_direct_connection
    hosts = await asyncio.shield(host_resolved)
  File "/home/pi/.local/lib/python3.9/site-packages/aiohttp/connector.py", line 865, in _resolve_host
    addrs = await self._resolver.resolve(host, port, family=self._family)
  File "/home/pi/.local/lib/python3.9/site-packages/aiohttp/resolver.py", line 31, in resolve
    infos = await self._loop.getaddrinfo(
  File "/usr/lib/python3.9/asyncio/base_events.py", line 856, in getaddrinfo
    return await self.run_in_executor(
  File "/usr/lib/python3.9/concurrent/futures/thread.py", line 52, in run
    result = self.fn(*self.args, **self.kwargs)
  File "/usr/lib/python3.9/socket.py", line 953, in getaddrinfo
    for res in _socket.getaddrinfo(host, port, family, type, proto, flags):
socket.gaierror: [Errno -3] Temporary failure in name resolution

The above exception was the direct cause of the following exception:

Traceback (most recent call last):
  File "/home/pi/.local/lib/python3.9/site-packages/discord/client.py", line 563, in connect
    self.ws = await asyncio.wait_for(coro, timeout=60.0)
  File "/usr/lib/python3.9/asyncio/tasks.py", line 481, in wait_for
    return fut.result()
  File "/home/pi/.local/lib/python3.9/site-packages/discord/gateway.py", line 305, in from_client
    gateway = gateway or await client.http.get_gateway()
  File "/home/pi/.local/lib/python3.9/site-packages/discord/http.py", line 967, in get_gateway
    data = await self.request(Route('GET', '/gateway'))
  File "/home/pi/.local/lib/python3.9/site-packages/discord/http.py", line 192, in request
    async with self.__session.request(method, url, **kwargs) as r:
  File "/home/pi/.local/lib/python3.9/site-packages/aiohttp/client.py", line 1117, in __aenter__
    self._resp = await self._coro
  File "/home/pi/.local/lib/python3.9/site-packages/aiohttp/client.py", line 520, in _request
    conn = await self._connector.connect(
  File "/home/pi/.local/lib/python3.9/site-packages/aiohttp/connector.py", line 535, in connect
    proto = await self._create_connection(req, traces, timeout)
  File "/home/pi/.local/lib/python3.9/site-packages/aiohttp/connector.py", line 892, in _create_connection
    _, proto = await self._create_direct_connection(req, traces, timeout)
  File "/home/pi/.local/lib/python3.9/site-packages/aiohttp/connector.py", line 1011, in _create_direct_connection
    raise ClientConnectorError(req.connection_key, exc) from exc
aiohttp.client_exceptions.ClientConnectorError: Cannot connect to host discord.com:443 ssl:default [Temporary failure in name resolution]
2022-07-01 12:58:33,643:ERROR:discord.client: Attempting a reconnect in 1.97s
Traceback (most recent call last):
  File "/home/pi/.local/lib/python3.9/site-packages/aiohttp/connector.py", line 969, in _wrap_create_connection
    return await self._loop.create_connection(*args, **kwargs)  # type: ignore  # noqa
  File "/usr/lib/python3.9/asyncio/base_events.py", line 1081, in create_connection
    transport, protocol = await self._create_connection_transport(
  File "/usr/lib/python3.9/asyncio/base_events.py", line 1111, in _create_connection_transport
    await waiter
  File "/usr/lib/python3.9/asyncio/sslproto.py", line 528, in data_received
    ssldata, appdata = self._sslpipe.feed_ssldata(data)
  File "/usr/lib/python3.9/asyncio/sslproto.py", line 188, in feed_ssldata
    self._sslobj.do_handshake()
  File "/usr/lib/python3.9/ssl.py", line 944, in do_handshake
    self._sslobj.do_handshake()
ssl.SSLCertVerificationError: [SSL: CERTIFICATE_VERIFY_FAILED] certificate verify failed: EE certificate key too weak (_ssl.c:1123)

The above exception was the direct cause of the following exception:

Traceback (most recent call last):
  File "/home/pi/.local/lib/python3.9/site-packages/discord/client.py", line 563, in connect
    self.ws = await asyncio.wait_for(coro, timeout=60.0)
  File "/usr/lib/python3.9/asyncio/tasks.py", line 481, in wait_for
    return fut.result()
  File "/home/pi/.local/lib/python3.9/site-packages/discord/gateway.py", line 305, in from_client
    gateway = gateway or await client.http.get_gateway()
  File "/home/pi/.local/lib/python3.9/site-packages/discord/http.py", line 967, in get_gateway
    data = await self.request(Route('GET', '/gateway'))
  File "/home/pi/.local/lib/python3.9/site-packages/discord/http.py", line 192, in request
    async with self.__session.request(method, url, **kwargs) as r:
  File "/home/pi/.local/lib/python3.9/site-packages/aiohttp/client.py", line 1117, in __aenter__
    self._resp = await self._coro
  File "/home/pi/.local/lib/python3.9/site-packages/aiohttp/client.py", line 520, in _request
    conn = await self._connector.connect(
  File "/home/pi/.local/lib/python3.9/site-packages/aiohttp/connector.py", line 535, in connect
    proto = await self._create_connection(req, traces, timeout)
  File "/home/pi/.local/lib/python3.9/site-packages/aiohttp/connector.py", line 892, in _create_connection
    _, proto = await self._create_direct_connection(req, traces, timeout)
  File "/home/pi/.local/lib/python3.9/site-packages/aiohttp/connector.py", line 1051, in _create_direct_connection
    raise last_exc
  File "/home/pi/.local/lib/python3.9/site-packages/aiohttp/connector.py", line 1020, in _create_direct_connection
    transp, proto = await self._wrap_create_connection(
  File "/home/pi/.local/lib/python3.9/site-packages/aiohttp/connector.py", line 971, in _wrap_create_connection
    raise ClientConnectorCertificateError(req.connection_key, exc) from exc
aiohttp.client_exceptions.ClientConnectorCertificateError: Cannot connect to host discord.com:443 ssl:True [SSLCertVerificationError: (1, '[SSL: CERTIFICATE_VERIFY_FAILED] certificate verify failed: EE certificate key too weak (_ssl.c:1123)')]
2022-07-01 12:58:35,684:ERROR:discord.client: Attempting a reconnect in 3.88s
Traceback (most recent call last):
  File "/home/pi/.local/lib/python3.9/site-packages/aiohttp/connector.py", line 969, in _wrap_create_connection
    return await self._loop.create_connection(*args, **kwargs)  # type: ignore  # noqa
  File "/usr/lib/python3.9/asyncio/base_events.py", line 1081, in create_connection
    transport, protocol = await self._create_connection_transport(
  File "/usr/lib/python3.9/asyncio/base_events.py", line 1111, in _create_connection_transport
    await waiter
  File "/usr/lib/python3.9/asyncio/sslproto.py", line 528, in data_received
    ssldata, appdata = self._sslpipe.feed_ssldata(data)
  File "/usr/lib/python3.9/asyncio/sslproto.py", line 188, in feed_ssldata
    self._sslobj.do_handshake()
  File "/usr/lib/python3.9/ssl.py", line 944, in do_handshake
    self._sslobj.do_handshake()
ssl.SSLCertVerificationError: [SSL: CERTIFICATE_VERIFY_FAILED] certificate verify failed: EE certificate key too weak (_ssl.c:1123)

The above exception was the direct cause of the following exception:

Traceback (most recent call last):
  File "/home/pi/.local/lib/python3.9/site-packages/discord/client.py", line 563, in connect
    self.ws = await asyncio.wait_for(coro, timeout=60.0)
  File "/usr/lib/python3.9/asyncio/tasks.py", line 481, in wait_for
    return fut.result()
  File "/home/pi/.local/lib/python3.9/site-packages/discord/gateway.py", line 305, in from_client
    gateway = gateway or await client.http.get_gateway()
  File "/home/pi/.local/lib/python3.9/site-packages/discord/http.py", line 967, in get_gateway
    data = await self.request(Route('GET', '/gateway'))
  File "/home/pi/.local/lib/python3.9/site-packages/discord/http.py", line 192, in request
    async with self.__session.request(method, url, **kwargs) as r:
  File "/home/pi/.local/lib/python3.9/site-packages/aiohttp/client.py", line 1117, in __aenter__
    self._resp = await self._coro
  File "/home/pi/.local/lib/python3.9/site-packages/aiohttp/client.py", line 520, in _request
    conn = await self._connector.connect(
  File "/home/pi/.local/lib/python3.9/site-packages/aiohttp/connector.py", line 535, in connect
    proto = await self._create_connection(req, traces, timeout)
  File "/home/pi/.local/lib/python3.9/site-packages/aiohttp/connector.py", line 892, in _create_connection
    _, proto = await self._create_direct_connection(req, traces, timeout)
  File "/home/pi/.local/lib/python3.9/site-packages/aiohttp/connector.py", line 1051, in _create_direct_connection
    raise last_exc
  File "/home/pi/.local/lib/python3.9/site-packages/aiohttp/connector.py", line 1020, in _create_direct_connection
    transp, proto = await self._wrap_create_connection(
  File "/home/pi/.local/lib/python3.9/site-packages/aiohttp/connector.py", line 971, in _wrap_create_connection
    raise ClientConnectorCertificateError(req.connection_key, exc) from exc
aiohttp.client_exceptions.ClientConnectorCertificateError: Cannot connect to host discord.com:443 ssl:True [SSLCertVerificationError: (1, '[SSL: CERTIFICATE_VERIFY_FAILED] certificate verify failed: EE certificate key too weak (_ssl.c:1123)')]
2022-07-01 12:58:39,626:ERROR:discord.client: Attempting a reconnect in 1.37s
Traceback (most recent call last):
  File "/home/pi/.local/lib/python3.9/site-packages/aiohttp/connector.py", line 969, in _wrap_create_connection
    return await self._loop.create_connection(*args, **kwargs)  # type: ignore  # noqa
  File "/usr/lib/python3.9/asyncio/base_events.py", line 1081, in create_connection
    transport, protocol = await self._create_connection_transport(
  File "/usr/lib/python3.9/asyncio/base_events.py", line 1111, in _create_connection_transport
    await waiter
  File "/usr/lib/python3.9/asyncio/sslproto.py", line 528, in data_received
    ssldata, appdata = self._sslpipe.feed_ssldata(data)
  File "/usr/lib/python3.9/asyncio/sslproto.py", line 188, in feed_ssldata
    self._sslobj.do_handshake()
  File "/usr/lib/python3.9/ssl.py", line 944, in do_handshake
    self._sslobj.do_handshake()
ssl.SSLCertVerificationError: [SSL: CERTIFICATE_VERIFY_FAILED] certificate verify failed: EE certificate key too weak (_ssl.c:1123)

The above exception was the direct cause of the following exception:

Traceback (most recent call last):
  File "/home/pi/.local/lib/python3.9/site-packages/discord/client.py", line 563, in connect
    self.ws = await asyncio.wait_for(coro, timeout=60.0)
  File "/usr/lib/python3.9/asyncio/tasks.py", line 481, in wait_for
    return fut.result()
  File "/home/pi/.local/lib/python3.9/site-packages/discord/gateway.py", line 305, in from_client
    gateway = gateway or await client.http.get_gateway()
  File "/home/pi/.local/lib/python3.9/site-packages/discord/http.py", line 967, in get_gateway
    data = await self.request(Route('GET', '/gateway'))
  File "/home/pi/.local/lib/python3.9/site-packages/discord/http.py", line 192, in request
    async with self.__session.request(method, url, **kwargs) as r:
  File "/home/pi/.local/lib/python3.9/site-packages/aiohttp/client.py", line 1117, in __aenter__
    self._resp = await self._coro
  File "/home/pi/.local/lib/python3.9/site-packages/aiohttp/client.py", line 520, in _request
    conn = await self._connector.connect(
  File "/home/pi/.local/lib/python3.9/site-packages/aiohttp/connector.py", line 535, in connect
    proto = await self._create_connection(req, traces, timeout)
  File "/home/pi/.local/lib/python3.9/site-packages/aiohttp/connector.py", line 892, in _create_connection
    _, proto = await self._create_direct_connection(req, traces, timeout)
  File "/home/pi/.local/lib/python3.9/site-packages/aiohttp/connector.py", line 1051, in _create_direct_connection
    raise last_exc
  File "/home/pi/.local/lib/python3.9/site-packages/aiohttp/connector.py", line 1020, in _create_direct_connection
    transp, proto = await self._wrap_create_connection(
  File "/home/pi/.local/lib/python3.9/site-packages/aiohttp/connector.py", line 971, in _wrap_create_connection
    raise ClientConnectorCertificateError(req.connection_key, exc) from exc
aiohttp.client_exceptions.ClientConnectorCertificateError: Cannot connect to host discord.com:443 ssl:True [SSLCertVerificationError: (1, '[SSL: CERTIFICATE_VERIFY_FAILED] certificate verify failed: EE certificate key too weak (_ssl.c:1123)')]
2022-07-01 12:58:41,057:ERROR:discord.client: Attempting a reconnect in 1.44s
Traceback (most recent call last):
  File "/home/pi/.local/lib/python3.9/site-packages/aiohttp/connector.py", line 969, in _wrap_create_connection
    return await self._loop.create_connection(*args, **kwargs)  # type: ignore  # noqa
  File "/usr/lib/python3.9/asyncio/base_events.py", line 1081, in create_connection
    transport, protocol = await self._create_connection_transport(
  File "/usr/lib/python3.9/asyncio/base_events.py", line 1111, in _create_connection_transport
    await waiter
  File "/usr/lib/python3.9/asyncio/sslproto.py", line 528, in data_received
    ssldata, appdata = self._sslpipe.feed_ssldata(data)
  File "/usr/lib/python3.9/asyncio/sslproto.py", line 188, in feed_ssldata
    self._sslobj.do_handshake()
  File "/usr/lib/python3.9/ssl.py", line 944, in do_handshake
    self._sslobj.do_handshake()
ssl.SSLCertVerificationError: [SSL: CERTIFICATE_VERIFY_FAILED] certificate verify failed: EE certificate key too weak (_ssl.c:1123)

The above exception was the direct cause of the following exception:

Traceback (most recent call last):
  File "/home/pi/.local/lib/python3.9/site-packages/discord/client.py", line 563, in connect
    self.ws = await asyncio.wait_for(coro, timeout=60.0)
  File "/usr/lib/python3.9/asyncio/tasks.py", line 481, in wait_for
    return fut.result()
  File "/home/pi/.local/lib/python3.9/site-packages/discord/gateway.py", line 305, in from_client
    gateway = gateway or await client.http.get_gateway()
  File "/home/pi/.local/lib/python3.9/site-packages/discord/http.py", line 967, in get_gateway
    data = await self.request(Route('GET', '/gateway'))
  File "/home/pi/.local/lib/python3.9/site-packages/discord/http.py", line 192, in request
    async with self.__session.request(method, url, **kwargs) as r:
  File "/home/pi/.local/lib/python3.9/site-packages/aiohttp/client.py", line 1117, in __aenter__
    self._resp = await self._coro
  File "/home/pi/.local/lib/python3.9/site-packages/aiohttp/client.py", line 520, in _request
    conn = await self._connector.connect(
  File "/home/pi/.local/lib/python3.9/site-packages/aiohttp/connector.py", line 535, in connect
    proto = await self._create_connection(req, traces, timeout)
  File "/home/pi/.local/lib/python3.9/site-packages/aiohttp/connector.py", line 892, in _create_connection
    _, proto = await self._create_direct_connection(req, traces, timeout)
  File "/home/pi/.local/lib/python3.9/site-packages/aiohttp/connector.py", line 1051, in _create_direct_connection
    raise last_exc
  File "/home/pi/.local/lib/python3.9/site-packages/aiohttp/connector.py", line 1020, in _create_direct_connection
    transp, proto = await self._wrap_create_connection(
  File "/home/pi/.local/lib/python3.9/site-packages/aiohttp/connector.py", line 971, in _wrap_create_connection
    raise ClientConnectorCertificateError(req.connection_key, exc) from exc
aiohttp.client_exceptions.ClientConnectorCertificateError: Cannot connect to host discord.com:443 ssl:True [SSLCertVerificationError: (1, '[SSL: CERTIFICATE_VERIFY_FAILED] certificate verify failed: EE certificate key too weak (_ssl.c:1123)')]
2022-07-01 12:58:42,554:ERROR:discord.client: Attempting a reconnect in 20.43s
Traceback (most recent call last):
  File "/home/pi/.local/lib/python3.9/site-packages/aiohttp/connector.py", line 969, in _wrap_create_connection
    return await self._loop.create_connection(*args, **kwargs)  # type: ignore  # noqa
  File "/usr/lib/python3.9/asyncio/base_events.py", line 1081, in create_connection
    transport, protocol = await self._create_connection_transport(
  File "/usr/lib/python3.9/asyncio/base_events.py", line 1111, in _create_connection_transport
    await waiter
  File "/usr/lib/python3.9/asyncio/sslproto.py", line 528, in data_received
    ssldata, appdata = self._sslpipe.feed_ssldata(data)
  File "/usr/lib/python3.9/asyncio/sslproto.py", line 188, in feed_ssldata
    self._sslobj.do_handshake()
  File "/usr/lib/python3.9/ssl.py", line 944, in do_handshake
    self._sslobj.do_handshake()
ssl.SSLCertVerificationError: [SSL: CERTIFICATE_VERIFY_FAILED] certificate verify failed: EE certificate key too weak (_ssl.c:1123)

The above exception was the direct cause of the following exception:

Traceback (most recent call last):
  File "/home/pi/.local/lib/python3.9/site-packages/discord/client.py", line 563, in connect
    self.ws = await asyncio.wait_for(coro, timeout=60.0)
  File "/usr/lib/python3.9/asyncio/tasks.py", line 481, in wait_for
    return fut.result()
  File "/home/pi/.local/lib/python3.9/site-packages/discord/gateway.py", line 305, in from_client
    gateway = gateway or await client.http.get_gateway()
  File "/home/pi/.local/lib/python3.9/site-packages/discord/http.py", line 967, in get_gateway
    data = await self.request(Route('GET', '/gateway'))
  File "/home/pi/.local/lib/python3.9/site-packages/discord/http.py", line 192, in request
    async with self.__session.request(method, url, **kwargs) as r:
  File "/home/pi/.local/lib/python3.9/site-packages/aiohttp/client.py", line 1117, in __aenter__
    self._resp = await self._coro
  File "/home/pi/.local/lib/python3.9/site-packages/aiohttp/client.py", line 520, in _request
    conn = await self._connector.connect(
  File "/home/pi/.local/lib/python3.9/site-packages/aiohttp/connector.py", line 535, in connect
    proto = await self._create_connection(req, traces, timeout)
  File "/home/pi/.local/lib/python3.9/site-packages/aiohttp/connector.py", line 892, in _create_connection
    _, proto = await self._create_direct_connection(req, traces, timeout)
  File "/home/pi/.local/lib/python3.9/site-packages/aiohttp/connector.py", line 1051, in _create_direct_connection
    raise last_exc
  File "/home/pi/.local/lib/python3.9/site-packages/aiohttp/connector.py", line 1020, in _create_direct_connection
    transp, proto = await self._wrap_create_connection(
  File "/home/pi/.local/lib/python3.9/site-packages/aiohttp/connector.py", line 971, in _wrap_create_connection
    raise ClientConnectorCertificateError(req.connection_key, exc) from exc
aiohttp.client_exceptions.ClientConnectorCertificateError: Cannot connect to host discord.com:443 ssl:True [SSLCertVerificationError: (1, '[SSL: CERTIFICATE_VERIFY_FAILED] certificate verify failed: EE certificate key too weak (_ssl.c:1123)')]
2022-07-01 12:59:03,078:ERROR:discord.client: Attempting a reconnect in 57.57s
Traceback (most recent call last):
  File "/home/pi/.local/lib/python3.9/site-packages/aiohttp/connector.py", line 969, in _wrap_create_connection
    return await self._loop.create_connection(*args, **kwargs)  # type: ignore  # noqa
  File "/usr/lib/python3.9/asyncio/base_events.py", line 1081, in create_connection
    transport, protocol = await self._create_connection_transport(
  File "/usr/lib/python3.9/asyncio/base_events.py", line 1111, in _create_connection_transport
    await waiter
  File "/usr/lib/python3.9/asyncio/sslproto.py", line 528, in data_received
    ssldata, appdata = self._sslpipe.feed_ssldata(data)
  File "/usr/lib/python3.9/asyncio/sslproto.py", line 188, in feed_ssldata
    self._sslobj.do_handshake()
  File "/usr/lib/python3.9/ssl.py", line 944, in do_handshake
    self._sslobj.do_handshake()
ssl.SSLCertVerificationError: [SSL: CERTIFICATE_VERIFY_FAILED] certificate verify failed: EE certificate key too weak (_ssl.c:1123)

The above exception was the direct cause of the following exception:

Traceback (most recent call last):
  File "/home/pi/.local/lib/python3.9/site-packages/discord/client.py", line 563, in connect
    self.ws = await asyncio.wait_for(coro, timeout=60.0)
  File "/usr/lib/python3.9/asyncio/tasks.py", line 481, in wait_for
    return fut.result()
  File "/home/pi/.local/lib/python3.9/site-packages/discord/gateway.py", line 305, in from_client
    gateway = gateway or await client.http.get_gateway()
  File "/home/pi/.local/lib/python3.9/site-packages/discord/http.py", line 967, in get_gateway
    data = await self.request(Route('GET', '/gateway'))
  File "/home/pi/.local/lib/python3.9/site-packages/discord/http.py", line 192, in request
    async with self.__session.request(method, url, **kwargs) as r:
  File "/home/pi/.local/lib/python3.9/site-packages/aiohttp/client.py", line 1117, in __aenter__
    self._resp = await self._coro
  File "/home/pi/.local/lib/python3.9/site-packages/aiohttp/client.py", line 520, in _request
    conn = await self._connector.connect(
  File "/home/pi/.local/lib/python3.9/site-packages/aiohttp/connector.py", line 535, in connect
    proto = await self._create_connection(req, traces, timeout)
  File "/home/pi/.local/lib/python3.9/site-packages/aiohttp/connector.py", line 892, in _create_connection
    _, proto = await self._create_direct_connection(req, traces, timeout)
  File "/home/pi/.local/lib/python3.9/site-packages/aiohttp/connector.py", line 1051, in _create_direct_connection
    raise last_exc
  File "/home/pi/.local/lib/python3.9/site-packages/aiohttp/connector.py", line 1020, in _create_direct_connection
    transp, proto = await self._wrap_create_connection(
  File "/home/pi/.local/lib/python3.9/site-packages/aiohttp/connector.py", line 971, in _wrap_create_connection
    raise ClientConnectorCertificateError(req.connection_key, exc) from exc
aiohttp.client_exceptions.ClientConnectorCertificateError: Cannot connect to host discord.com:443 ssl:True [SSLCertVerificationError: (1, '[SSL: CERTIFICATE_VERIFY_FAILED] certificate verify failed: EE certificate key too weak (_ssl.c:1123)')]
2022-07-01 13:00:05,720:ERROR:discord.client: Attempting a reconnect in 92.81s
Traceback (most recent call last):
  File "/home/pi/.local/lib/python3.9/site-packages/aiohttp/connector.py", line 999, in _create_direct_connection
    hosts = await asyncio.shield(host_resolved)
  File "/home/pi/.local/lib/python3.9/site-packages/aiohttp/connector.py", line 865, in _resolve_host
    addrs = await self._resolver.resolve(host, port, family=self._family)
  File "/home/pi/.local/lib/python3.9/site-packages/aiohttp/resolver.py", line 31, in resolve
    infos = await self._loop.getaddrinfo(
  File "/usr/lib/python3.9/asyncio/base_events.py", line 856, in getaddrinfo
    return await self.run_in_executor(
  File "/usr/lib/python3.9/concurrent/futures/thread.py", line 52, in run
    result = self.fn(*self.args, **self.kwargs)
  File "/usr/lib/python3.9/socket.py", line 953, in getaddrinfo
    for res in _socket.getaddrinfo(host, port, family, type, proto, flags):
socket.gaierror: [Errno -3] Temporary failure in name resolution

The above exception was the direct cause of the following exception:

Traceback (most recent call last):
  File "/home/pi/.local/lib/python3.9/site-packages/discord/client.py", line 563, in connect
    self.ws = await asyncio.wait_for(coro, timeout=60.0)
  File "/usr/lib/python3.9/asyncio/tasks.py", line 481, in wait_for
    return fut.result()
  File "/home/pi/.local/lib/python3.9/site-packages/discord/gateway.py", line 305, in from_client
    gateway = gateway or await client.http.get_gateway()
  File "/home/pi/.local/lib/python3.9/site-packages/discord/http.py", line 967, in get_gateway
    data = await self.request(Route('GET', '/gateway'))
  File "/home/pi/.local/lib/python3.9/site-packages/discord/http.py", line 192, in request
    async with self.__session.request(method, url, **kwargs) as r:
  File "/home/pi/.local/lib/python3.9/site-packages/aiohttp/client.py", line 1117, in __aenter__
    self._resp = await self._coro
  File "/home/pi/.local/lib/python3.9/site-packages/aiohttp/client.py", line 520, in _request
    conn = await self._connector.connect(
  File "/home/pi/.local/lib/python3.9/site-packages/aiohttp/connector.py", line 535, in connect
    proto = await self._create_connection(req, traces, timeout)
  File "/home/pi/.local/lib/python3.9/site-packages/aiohttp/connector.py", line 892, in _create_connection
    _, proto = await self._create_direct_connection(req, traces, timeout)
  File "/home/pi/.local/lib/python3.9/site-packages/aiohttp/connector.py", line 1011, in _create_direct_connection
    raise ClientConnectorError(req.connection_key, exc) from exc
aiohttp.client_exceptions.ClientConnectorError: Cannot connect to host discord.com:443 ssl:default [Temporary failure in name resolution]
2022-07-01 13:01:38,691:ERROR:discord.client: Attempting a reconnect in 226.35s
Traceback (most recent call last):
  File "/home/pi/.local/lib/python3.9/site-packages/aiohttp/connector.py", line 969, in _wrap_create_connection
    return await self._loop.create_connection(*args, **kwargs)  # type: ignore  # noqa
  File "/usr/lib/python3.9/asyncio/base_events.py", line 1081, in create_connection
    transport, protocol = await self._create_connection_transport(
  File "/usr/lib/python3.9/asyncio/base_events.py", line 1111, in _create_connection_transport
    await waiter
  File "/usr/lib/python3.9/asyncio/sslproto.py", line 528, in data_received
    ssldata, appdata = self._sslpipe.feed_ssldata(data)
  File "/usr/lib/python3.9/asyncio/sslproto.py", line 188, in feed_ssldata
    self._sslobj.do_handshake()
  File "/usr/lib/python3.9/ssl.py", line 944, in do_handshake
    self._sslobj.do_handshake()
ssl.SSLCertVerificationError: [SSL: CERTIFICATE_VERIFY_FAILED] certificate verify failed: EE certificate key too weak (_ssl.c:1123)

The above exception was the direct cause of the following exception:

Traceback (most recent call last):
  File "/home/pi/.local/lib/python3.9/site-packages/discord/client.py", line 563, in connect
    self.ws = await asyncio.wait_for(coro, timeout=60.0)
  File "/usr/lib/python3.9/asyncio/tasks.py", line 481, in wait_for
    return fut.result()
  File "/home/pi/.local/lib/python3.9/site-packages/discord/gateway.py", line 305, in from_client
    gateway = gateway or await client.http.get_gateway()
  File "/home/pi/.local/lib/python3.9/site-packages/discord/http.py", line 967, in get_gateway
    data = await self.request(Route('GET', '/gateway'))
  File "/home/pi/.local/lib/python3.9/site-packages/discord/http.py", line 192, in request
    async with self.__session.request(method, url, **kwargs) as r:
  File "/home/pi/.local/lib/python3.9/site-packages/aiohttp/client.py", line 1117, in __aenter__
    self._resp = await self._coro
  File "/home/pi/.local/lib/python3.9/site-packages/aiohttp/client.py", line 520, in _request
    conn = await self._connector.connect(
  File "/home/pi/.local/lib/python3.9/site-packages/aiohttp/connector.py", line 535, in connect
    proto = await self._create_connection(req, traces, timeout)
  File "/home/pi/.local/lib/python3.9/site-packages/aiohttp/connector.py", line 892, in _create_connection
    _, proto = await self._create_direct_connection(req, traces, timeout)
  File "/home/pi/.local/lib/python3.9/site-packages/aiohttp/connector.py", line 1051, in _create_direct_connection
    raise last_exc
  File "/home/pi/.local/lib/python3.9/site-packages/aiohttp/connector.py", line 1020, in _create_direct_connection
    transp, proto = await self._wrap_create_connection(
  File "/home/pi/.local/lib/python3.9/site-packages/aiohttp/connector.py", line 971, in _wrap_create_connection
    raise ClientConnectorCertificateError(req.connection_key, exc) from exc
aiohttp.client_exceptions.ClientConnectorCertificateError: Cannot connect to host discord.com:443 ssl:True [SSLCertVerificationError: (1, '[SSL: CERTIFICATE_VERIFY_FAILED] certificate verify failed: EE certificate key too weak (_ssl.c:1123)')]
2022-07-01 13:05:25,184:ERROR:discord.client: Attempting a reconnect in 275.40s
Traceback (most recent call last):
  File "/home/pi/.local/lib/python3.9/site-packages/aiohttp/connector.py", line 969, in _wrap_create_connection
    return await self._loop.create_connection(*args, **kwargs)  # type: ignore  # noqa
  File "/usr/lib/python3.9/asyncio/base_events.py", line 1081, in create_connection
    transport, protocol = await self._create_connection_transport(
  File "/usr/lib/python3.9/asyncio/base_events.py", line 1111, in _create_connection_transport
    await waiter
  File "/usr/lib/python3.9/asyncio/sslproto.py", line 528, in data_received
    ssldata, appdata = self._sslpipe.feed_ssldata(data)
  File "/usr/lib/python3.9/asyncio/sslproto.py", line 188, in feed_ssldata
    self._sslobj.do_handshake()
  File "/usr/lib/python3.9/ssl.py", line 944, in do_handshake
    self._sslobj.do_handshake()
ssl.SSLCertVerificationError: [SSL: CERTIFICATE_VERIFY_FAILED] certificate verify failed: EE certificate key too weak (_ssl.c:1123)

The above exception was the direct cause of the following exception:

Traceback (most recent call last):
  File "/home/pi/.local/lib/python3.9/site-packages/discord/client.py", line 563, in connect
    self.ws = await asyncio.wait_for(coro, timeout=60.0)
  File "/usr/lib/python3.9/asyncio/tasks.py", line 481, in wait_for
    return fut.result()
  File "/home/pi/.local/lib/python3.9/site-packages/discord/gateway.py", line 305, in from_client
    gateway = gateway or await client.http.get_gateway()
  File "/home/pi/.local/lib/python3.9/site-packages/discord/http.py", line 967, in get_gateway
    data = await self.request(Route('GET', '/gateway'))
  File "/home/pi/.local/lib/python3.9/site-packages/discord/http.py", line 192, in request
    async with self.__session.request(method, url, **kwargs) as r:
  File "/home/pi/.local/lib/python3.9/site-packages/aiohttp/client.py", line 1117, in __aenter__
    self._resp = await self._coro
  File "/home/pi/.local/lib/python3.9/site-packages/aiohttp/client.py", line 520, in _request
    conn = await self._connector.connect(
  File "/home/pi/.local/lib/python3.9/site-packages/aiohttp/connector.py", line 535, in connect
    proto = await self._create_connection(req, traces, timeout)
  File "/home/pi/.local/lib/python3.9/site-packages/aiohttp/connector.py", line 892, in _create_connection
    _, proto = await self._create_direct_connection(req, traces, timeout)
  File "/home/pi/.local/lib/python3.9/site-packages/aiohttp/connector.py", line 1051, in _create_direct_connection
    raise last_exc
  File "/home/pi/.local/lib/python3.9/site-packages/aiohttp/connector.py", line 1020, in _create_direct_connection
    transp, proto = await self._wrap_create_connection(
  File "/home/pi/.local/lib/python3.9/site-packages/aiohttp/connector.py", line 971, in _wrap_create_connection
    raise ClientConnectorCertificateError(req.connection_key, exc) from exc
aiohttp.client_exceptions.ClientConnectorCertificateError: Cannot connect to host discord.com:443 ssl:True [SSLCertVerificationError: (1, '[SSL: CERTIFICATE_VERIFY_FAILED] certificate verify failed: EE certificate key too weak (_ssl.c:1123)')]
2022-07-05 12:37:59,086:ERROR:discord.client: Attempting a reconnect in 1.82s
Traceback (most recent call last):
  File "/home/pi/.local/lib/python3.9/site-packages/discord/gateway.py", line 306, in from_client
    socket = await client.http.ws_connect(gateway)
  File "/home/pi/.local/lib/python3.9/site-packages/discord/http.py", line 132, in ws_connect
    return await self.__session.ws_connect(url, **kwargs)
  File "/home/pi/.local/lib/python3.9/site-packages/aiohttp/client.py", line 754, in _ws_connect
    resp = await self.request(
  File "/home/pi/.local/lib/python3.9/site-packages/aiohttp/client.py", line 520, in _request
    conn = await self._connector.connect(
  File "/home/pi/.local/lib/python3.9/site-packages/aiohttp/connector.py", line 535, in connect
    proto = await self._create_connection(req, traces, timeout)
  File "/home/pi/.local/lib/python3.9/site-packages/aiohttp/connector.py", line 892, in _create_connection
    _, proto = await self._create_direct_connection(req, traces, timeout)
  File "/home/pi/.local/lib/python3.9/site-packages/aiohttp/connector.py", line 1020, in _create_direct_connection
    transp, proto = await self._wrap_create_connection(
  File "/home/pi/.local/lib/python3.9/site-packages/aiohttp/connector.py", line 969, in _wrap_create_connection
    return await self._loop.create_connection(*args, **kwargs)  # type: ignore  # noqa
  File "/usr/lib/python3.9/asyncio/base_events.py", line 1081, in create_connection
    transport, protocol = await self._create_connection_transport(
  File "/usr/lib/python3.9/asyncio/base_events.py", line 1111, in _create_connection_transport
    await waiter
asyncio.exceptions.CancelledError

During handling of the above exception, another exception occurred:

Traceback (most recent call last):
  File "/usr/lib/python3.9/asyncio/tasks.py", line 492, in wait_for
    fut.result()
asyncio.exceptions.CancelledError

The above exception was the direct cause of the following exception:

Traceback (most recent call last):
  File "/home/pi/.local/lib/python3.9/site-packages/discord/client.py", line 563, in connect
    self.ws = await asyncio.wait_for(coro, timeout=60.0)
  File "/usr/lib/python3.9/asyncio/tasks.py", line 494, in wait_for
    raise exceptions.TimeoutError() from exc
asyncio.exceptions.TimeoutError
